Workbook

Sheet Controle PCs
A1: Data Última Aprovação RC | B1: Data Pedido | C1: SLA Atendimento | D1: Comprador | E1: Área Requisitante | F1: Fornecedor | G1: Tipo | H1: Material / Serviço | I1: SLA Padrão | J1: Atrasada / No prazo | K1: Δ SLA Padrão x SLA Atendimento | L1: Preço Histórico | M1: Proposta Inicial | N1: Proposta Negociada | O1: Moeda | P1: Saving + Cost Total | Q1: % Redução | R1: Modalidade | S1: RC | T1: Pedido Compras | U1: Previsão Entrega | V1: Follow Up | W1: NF | X1: RECEBIMENTO CONCLUÍDO? | Y1: FORNECEDOR LOCAL?
A2: 46209 | B2: 46206 | C2: =IF(OR(A2="",B2=""),"",B2-A2) -> -3 | D2: Amanda Salvi | E2: ADMINISTRATIVE | F2: Disk Limpeza Total Ltda | G2: Spot | H2: Material Urgente | I2: =IFERROR(VLOOKUP(H2,SLA_Ref!$A$1:$B$8,2,FALSE),"") -> 3 | J2: =IF(A2="","",IF(B2="",IF(TODAY()-A2>I2,"ATRASADA","EM ANDAMENTO"),IF(B2-A2>I2,"ATRASADA","NO PRAZO"))) -> NO PRAZO | K2: =Tabela2[[#This Row],[SLA Padrão]]-Tabela2[[#This Row],[SLA Atendimento]] -> 6 | M2: 448.01 | N2: 448.01 | O2: BRL | P2: =Tabela2[[#This Row],[Proposta Inicial]]-Tabela2[[#This Row],[Proposta Negociada]] -> 0 | Q2: =Tabela2[[#This Row],[Proposta Negociada]]/Tabela2[[#This Row],[Proposta Inicial]]-1 -> 0 | S2: RC 10001693 | T2: 450000024 | X2: Sim | Y2: Sim
A3: 46209 | B3: 46204 | C3: =IF(OR(A3="",B3=""),"",B3-A3) -> -5 | D3: Amanda Salvi | E3: ADMINISTRATIVE | F3: Idealiza Comercio de Utilidades Ltda | G3: Spot | H3: Material Urgente | I3: =IFERROR(VLOOKUP(H3,SLA_Ref!$A$1:$B$8,2,FALSE),"") -> 3 | J3: =IF(A3="","",IF(B3="",IF(TODAY()-A3>I3,"ATRASADA","EM ANDAMENTO"),IF(B3-A3>I3,"ATRASADA","NO PRAZO"))) -> NO PRAZO | K3: =Tabela2[[#This Row],[SLA Padrão]]-Tabela2[[#This Row],[SLA Atendimento]] -> 8 | M3: 51.9 | N3: 51.9 | O3: BRL | P3: =Tabela2[[#This Row],[Proposta Inicial]]-Tabela2[[#This Row],[Proposta Negociada]] -> 0 | Q3: =Tabela2[[#This Row],[Proposta Negociada]]/Tabela2[[#This Row],[Proposta Inicial]]-1 -> 0 | S3: RC 10001694 | T3: 450000024 | X3: Sim | Y3: Não
A4: 46202 | B4: 46205 | C4: =IF(OR(A4="",B4=""),"",B4-A4) -> 3 | D4: Michel Bernardes | E4: PROJECTS | F4: Mcr Plataformas | G4: Contrato | H4: Contrato Contínuo Simples | I4: =IFERROR(VLOOKUP(H4,SLA_Ref!$A$1:$B$8,2,FALSE),"") -> 30 | J4: =IF(A4="","",IF(B4="",IF(TODAY()-A4>I4,"ATRASADA","EM ANDAMENTO"),IF(B4-A4>I4,"ATRASADA","NO PRAZO"))) -> NO PRAZO | K4: =Tabela2[[#This Row],[SLA Padrão]]-Tabela2[[#This Row],[SLA Atendimento]] -> 27 | L4: 5900 | M4: =5900*12 -> 70800 | N4: =4200*12 -> 50400 | O4: BRL | P4: =Tabela2[[#This Row],[Proposta Inicial]]-Tabela2[[#This Row],[Proposta Negociada]] -> 20400 | Q4: =Tabela2[[#This Row],[Proposta Negociada]]/Tabela2[[#This Row],[Proposta Inicial]]-1 -> -0.28813559 | R4: Saving | S4: Locação PTA- Transferência de Contrato | T4: 450000170 | W4: 148 | X4: Mensal | Y4: Sim
A5: 46199 | B5: 46204 | C5: =IF(OR(A5="",B5=""),"",B5-A5) -> 5 | D5: Michel Bernardes | E5: GEOLOGICAL EXPLORATION | F5: Alpha Abras | G5: Spot | H5: Material Normal | I5: =IFERROR(VLOOKUP(H5,SLA_Ref!$A$1:$B$8,2,FALSE),"") -> 8 | J5: =IF(A5="","",IF(B5="",IF(TODAY()-A5>I5,"ATRASADA","EM ANDAMENTO"),IF(B5-A5>I5,"ATRASADA","NO PRAZO"))) -> NO PRAZO | K5: =Tabela2[[#This Row],[SLA Padrão]]-Tabela2[[#This Row],[SLA Atendimento]] -> 3 | M5: 137.8 | N5: 137.8 | O5: BRL | P5: =Tabela2[[#This Row],[Proposta Inicial]]-Tabela2[[#This Row],[Proposta Negociada]] -> 0 | Q5: =Tabela2[[#This Row],[Proposta Negociada]]/Tabela2[[#This Row],[Proposta Inicial]]-1 -> 0 | S5: RC10001658 | T5: 450000222 | W5: 213915 | X5: Sim | Y5: Sim
A6: 46202 | B6: 46204 | C6: =IF(OR(A6="",B6=""),"",B6-A6) -> 2 | D6: Michel Bernardes | E6: GEOLOGICAL EXPLORATION | F6: Comercial ArtPel | G6: Spot | H6: Material Normal | I6: =IFERROR(VLOOKUP(H6,SLA_Ref!$A$1:$B$8,2,FALSE),"") -> 8 | J6: =IF(A6="","",IF(B6="",IF(TODAY()-A6>I6,"ATRASADA","EM ANDAMENTO"),IF(B6-A6>I6,"ATRASADA","NO PRAZO"))) -> NO PRAZO | K6: =Tabela2[[#This Row],[SLA Padrão]]-Tabela2[[#This Row],[SLA Atendimento]] -> 6 | M6: 50 | N6: 50 | O6: BRL | P6: =Tabela2[[#This Row],[Proposta Inicial]]-Tabela2[[#This Row],[Proposta Negociada]] -> 0 | Q6: =Tabela2[[#This Row],[Proposta Negociada]]/Tabela2[[#This Row],[Proposta Inicial]]-1 -> 0 | S6: RC 10001655 | T6: 450000223 | W6: 54762 | X6: Sim | Y6: Sim
A7: 46202 | B7: 46204 | C7: =IF(OR(A7="",B7=""),"",B7-A7) -> 2 | D7: Amanda Salvi | E7: GEOLOGICAL EXPLORATION | F7: Sodre Miguel | G7: Spot | H7: Material Normal | I7: =IFERROR(VLOOKUP(H7,SLA_Ref!$A$1:$B$8,2,FALSE),"") -> 8 | J7: =IF(A7="","",IF(B7="",IF(TODAY()-A7>I7,"ATRASADA","EM ANDAMENTO"),IF(B7-A7>I7,"ATRASADA","NO PRAZO"))) -> NO PRAZO | K7: =Tabela2[[#This Row],[SLA Padrão]]-Tabela2[[#This Row],[SLA Atendimento]] -> 6 | M7: 18.98 | N7: 18.98 | O7: BRL | P7: =Tabela2[[#This Row],[Proposta Inicial]]-Tabela2[[#This Row],[Proposta Negociada]] -> 0 | Q7: =Tabela2[[#This Row],[Proposta Negociada]]/Tabela2[[#This Row],[Proposta Inicial]]-1 -> 0 | S7: RC 10001657 | T7: 450000224 | X7: Não | Y7: Sim
A8: 46203 | B8: 46205 | C8: =IF(OR(A8="",B8=""),"",B8-A8) -> 2 | D8: Michel Bernardes | E8: IT | F8: Ubiquiti Brazil | G8: Spot | H8: Material Urgente | I8: =IFERROR(VLOOKUP(H8,SLA_Ref!$A$1:$B$8,2,FALSE),"") -> 3 | J8: =IF(A8="","",IF(B8="",IF(TODAY()-A8>I8,"ATRASADA","EM ANDAMENTO"),IF(B8-A8>I8,"ATRASADA","NO PRAZO"))) -> NO PRAZO | K8: =Tabela2[[#This Row],[SLA Padrão]]-Tabela2[[#This Row],[SLA Atendimento]] -> 1 | M8: 3880 | N8: 3880 | O8: BRL | P8: =Tabela2[[#This Row],[Proposta Inicial]]-Tabela2[[#This Row],[Proposta Negociada]] -> 0 | Q8: =Tabela2[[#This Row],[Proposta Negociada]]/Tabela2[[#This Row],[Proposta Inicial]]-1 -> 0 | S8: RC 10001672 | T8: 450000226 | W8: 246857 | X8: Sim | Y8: Não
A9: 46204 | B9: 46205 | C9: =IF(OR(A9="",B9=""),"",B9-A9) -> 1 | D9: Michel Bernardes | E9: COMMUNITY RELATIONS | F9: MOVMED COMERCIO DE MOVEIS E PRODUTOS | G9: Spot | H9: Material Urgente | I9: =IFERROR(VLOOKUP(H9,SLA_Ref!$A$1:$B$8,2,FALSE),"") -> 3 | J9: =IF(A9="","",IF(B9="",IF(TODAY()-A9>I9,"ATRASADA","EM ANDAMENTO"),IF(B9-A9>I9,"ATRASADA","NO PRAZO"))) -> NO PRAZO | K9: =Tabela2[[#This Row],[SLA Padrão]]-Tabela2[[#This Row],[SLA Atendimento]] -> 2 | M9: 25591 | N9: 23800 | O9: BRL | P9: =Tabela2[[#This Row],[Proposta Inicial]]-Tabela2[[#This Row],[Proposta Negociada]] -> 1791 | Q9: =Tabela2[[#This Row],[Proposta Negociada]]/Tabela2[[#This Row],[Proposta Inicial]]-1 -> -0.069985542 | R9: Cost Avoidance | S9: RC 10001633 | T9: 450000227 | X9: Não | Y9: Não
A10: 46202 | B10: 46205 | C10: =IF(OR(A10="",B10=""),"",B10-A10) -> 3 | D10: Michel Bernardes | E10: GEOLOGICAL EXPLORATION | F10: Toque de Cor | G10: Spot | H10: Material Normal | I10: =IFERROR(VLOOKUP(H10,SLA_Ref!$A$1:$B$8,2,FALSE),"") -> 8 | J10: =IF(A10="","",IF(B10="",IF(TODAY()-A10>I10,"ATRASADA","EM ANDAMENTO"),IF(B10-A10>I10,"ATRASADA","NO PRAZO"))) -> NO PRAZO | K10: =Tabela2[[#This Row],[SLA Padrão]]-Tabela2[[#This Row],[SLA Atendimento]] -> 5 | M10: 63.99 | N10: 63.99 | O10: BRL | P10: =Tabela2[[#This Row],[Proposta Inicial]]-Tabela2[[#This Row],[Proposta Negociada]] -> 0 | Q10: =Tabela2[[#This Row],[Proposta Negociada]]/Tabela2[[#This Row],[Proposta Inicial]]-1 -> 0 | S10: RC 10001659 | T10: 450000228 | W10: 1912 | X10: Sim | Y10: Sim
A11: 46189 | B11: 46205 | C11: =IF(OR(A11="",B11=""),"",B11-A11) -> 16 | D11: Michel Bernardes | E11: ENVIRONMENT | F11: Sievert Laboratórios | G11: Spot | H11: Contrato Contínuo Simples | I11: 30 | J11: =IF(A11="","",IF(B11="",IF(TODAY()-A11>I11,"ATRASADA","EM ANDAMENTO"),IF(B11-A11>I11,"ATRASADA","NO PRAZO"))) -> NO PRAZO | K11: =Tabela2[[#This Row],[SLA Padrão]]-Tabela2[[#This Row],[SLA Atendimento]] -> 14 | M11: 120000 | N11: 108000 | O11: BRL | P11: =Tabela2[[#This Row],[Proposta Inicial]]-Tabela2[[#This Row],[Proposta Negociada]] -> 12000 | Q11: =Tabela2[[#This Row],[Proposta Negociada]]/Tabela2[[#This Row],[Proposta Inicial]]-1 -> -0.1 | R11: Cost Avoidance | S11: Programa de proteção radiológica CPTR | T11: 450000229 | W11: 87 | X11: Sim | Y11: Não
A12: 46203 | B12: 46206 | C12: =IF(OR(A12="",B12=""),"",B12-A12) -> 3 | D12: Michel Bernardes | E12: COMMUNITY RELATIONS | F12: PP Caponi | G12: Spot | H12: Material Normal | I12: =IFERROR(VLOOKUP(H12,SLA_Ref!$A$1:$B$8,2,FALSE),"") -> 8 | J12: =IF(A12="","",IF(B12="",IF(TODAY()-A12>I12,"ATRASADA","EM ANDAMENTO"),IF(B12-A12>I12,"ATRASADA","NO PRAZO"))) -> NO PRAZO | K12: =Tabela2[[#This Row],[SLA Padrão]]-Tabela2[[#This Row],[SLA Atendimento]] -> 5 | M12: 110 | N12: 110 | O12: BRL | P12: =Tabela2[[#This Row],[Proposta Inicial]]-Tabela2[[#This Row],[Proposta Negociada]] -> 0 | Q12: =Tabela2[[#This Row],[Proposta Negociada]]/Tabela2[[#This Row],[Proposta Inicial]]-1 -> 0 | S12: RC 10001667 - Cristal | T12: 450000231 | W12: 6612 | X12: Sim | Y12: Sim
A13: 46202 | B13: 46206 | C13: =IF(OR(A13="",B13=""),"",B13-A13) -> 4 | D13: Amanda Salvi | E13: SUSTAINABILITY | F13: Marcelo Batista | G13: Spot | H13: Serviço Normal | I13: =IFERROR(VLOOKUP(H13,SLA_Ref!$A$1:$B$8,2,FALSE),"") -> 15 | J13: =IF(A13="","",IF(B13="",IF(TODAY()-A13>I13,"ATRASADA","EM ANDAMENTO"),IF(B13-A13>I13,"ATRASADA","NO PRAZO"))) -> NO PRAZO | K13: =Tabela2[[#This Row],[SLA Padrão]]-Tabela2[[#This Row],[SLA Atendimento]] -> 11 | M13: 900 | N13: 800 | O13: BRL | P13: =Tabela2[[#This Row],[Proposta Inicial]]-Tabela2[[#This Row],[Proposta Negociada]] -> 100 | Q13: =Tabela2[[#This Row],[Proposta Negociada]]/Tabela2[[#This Row],[Proposta Inicial]]-1 -> -0.11111111 | R13: Cost Avoidance | S13: RC 10001564 | T13: 450000232 | X13: Não | Y13: Sim
A14: 46205 | B14: 46206 | C14: =IF(OR(A14="",B14=""),"",B14-A14) -> 1 | D14: Amanda Salvi | E14: CPTR | F14: Base Quimica SA | G14: Spot | H14: Material Urgente | I14: =IFERROR(VLOOKUP(H14,SLA_Ref!$A$1:$B$8,2,FALSE),"") -> 3 | J14: =IF(A14="","",IF(B14="",IF(TODAY()-A14>I14,"ATRASADA","EM ANDAMENTO"),IF(B14-A14>I14,"ATRASADA","NO PRAZO"))) -> NO PRAZO | K14: =Tabela2[[#This Row],[SLA Padrão]]-Tabela2[[#This Row],[SLA Atendimento]] -> 2 | M14: 8137.5 | N14: 8137.5 | O14: BRL | P14: =Tabela2[[#This Row],[Proposta Inicial]]-Tabela2[[#This Row],[Proposta Negociada]] -> 0 | Q14: =Tabela2[[#This Row],[Proposta Negociada]]/Tabela2[[#This Row],[Proposta Inicial]]-1 -> 0 | S14: RC 10001684 - Sulfato de Amônio (AmSul) para operação – CPTR | T14: 450000233 | W14: 564328 | X14: Sim | Y14: Não
A15: 46204 | B15: 46209 | C15: =IF(OR(A15="",B15=""),"",B15-A15) -> 5 | D15: Michel Bernardes | E15: HUMAN RESOURCES | F15: A C N PALMILHAS E BRINDES LTDA | G15: Spot | H15: Serviço Normal | I15: =IFERROR(VLOOKUP(H15,SLA_Ref!$A$1:$B$8,2,FALSE),"") -> 15 | J15: =IF(A15="","",IF(B15="",IF(TODAY()-A15>I15,"ATRASADA","EM ANDAMENTO"),IF(B15-A15>I15,"ATRASADA","NO PRAZO"))) -> NO PRAZO | K15: =Tabela2[[#This Row],[SLA Padrão]]-Tabela2[[#This Row],[SLA Atendimento]] -> 10 | M15: =14.95*100 -> 1495 | N15: =13.95*100 -> 1395 | O15: BRL | P15: =Tabela2[[#This Row],[Proposta Inicial]]-Tabela2[[#This Row],[Proposta Negociada]] -> 100 | Q15: =Tabela2[[#This Row],[Proposta Negociada]]/Tabela2[[#This Row],[Proposta Inicial]]-1 -> -0.066889632 | R15: Cost Avoidance | S15: RC 10001681 - MOUSE PAD ERGONÔMICO PERSONALIZADO Viridis | T15: 450000234 | W15: 23103 | X15: Sim | Y15: Não
A16: 46203 | B16: 46209 | C16: =IF(OR(A16="",B16=""),"",B16-A16) -> 6 | D16: Michel Bernardes | E16: COMMUNITY RELATIONS | F16: Cristais São Marcos | G16: Spot | H16: Serviço Normal | I16: =IFERROR(VLOOKUP(H16,SLA_Ref!$A$1:$B$8,2,FALSE),"") -> 15 | J16: =IF(A16="","",IF(B16="",IF(TODAY()-A16>I16,"ATRASADA","EM ANDAMENTO"),IF(B16-A16>I16,"ATRASADA","NO PRAZO"))) -> NO PRAZO | K16: =Tabela2[[#This Row],[SLA Padrão]]-Tabela2[[#This Row],[SLA Atendimento]] -> 9 | M16: 2051.8 | N16: 2051.8 | O16: BRL | P16: =Tabela2[[#This Row],[Proposta Inicial]]-Tabela2[[#This Row],[Proposta Negociada]] -> 0 | Q16: =Tabela2[[#This Row],[Proposta Negociada]]/Tabela2[[#This Row],[Proposta Inicial]]-1 -> 0 | S16: RC 10001667 - Cristal | T16: 450000235 | W16: 28281 | X16: Sim | Y16: Sim
A17: 46201 | B17: 46204 | C17: =IF(OR(A17="",B17=""),"",B17-A17) -> 3 | D17: Amanda Salvi | E17: ADMINISTRATIVE | F17: Tec Print Suprimentos e Assistencia | G17: Spot | H17: Serviço Normal | I17: =IFERROR(VLOOKUP(H17,SLA_Ref!$A$1:$B$8,2,FALSE),"") -> 15 | J17: =IF(A17="","",IF(B17="",IF(TODAY()-A17>I17,"ATRASADA","EM ANDAMENTO"),IF(B17-A17>I17,"ATRASADA","NO PRAZO"))) -> NO PRAZO | K17: =Tabela2[[#This Row],[SLA Padrão]]-Tabela2[[#This Row],[SLA Atendimento]] -> 12 | M17: 76.62 | N17: 76.62 | O17: BRL | P17: =Tabela2[[#This Row],[Proposta Inicial]]-Tabela2[[#This Row],[Proposta Negociada]] -> 0 | Q17: =Tabela2[[#This Row],[Proposta Negociada]]/Tabela2[[#This Row],[Proposta Inicial]]-1 -> 0 | S17: RC 10001645 | T17: 450000236 | X17: Não | Y17: Não
A18: 46192 | B18: 46206 | C18: =IF(OR(A18="",B18=""),"",B18-A18) -> 14 | D18: Amanda Salvi | E18: ADMINISTRATIVE | F18: Ebazar.com.br Utilidades Ltda | G18: Spot | H18: Serviço Normal | I18: =IFERROR(VLOOKUP(H18,SLA_Ref!$A$1:$B$8,2,FALSE),"") -> 15 | J18: =IF(A18="","",IF(B18="",IF(TODAY()-A18>I18,"ATRASADA","EM ANDAMENTO"),IF(B18-A18>I18,"ATRASADA","NO PRAZO"))) -> NO PRAZO | K18: =Tabela2[[#This Row],[SLA Padrão]]-Tabela2[[#This Row],[SLA Atendimento]] -> 1 | M18: 80 | N18: 80 | O18: BRL | P18: =Tabela2[[#This Row],[Proposta Inicial]]-Tabela2[[#This Row],[Proposta Negociada]] -> 0 | Q18: =Tabela2[[#This Row],[Proposta Negociada]]/Tabela2[[#This Row],[Proposta Inicial]]-1 -> 0 | S18: RC 10001624 | T18: 450000238 | X18: Não | Y18: Não
A19: 46205 | B19: 46199 | C19: =IF(OR(A19="",B19=""),"",B19-A19) -> -6 | D19: Júlia Guidorizzi | E19: CPTR | F19: WMF Brazil Ltda | G19: Spot | H19: Serviço Urgente | I19: =IFERROR(VLOOKUP(H19,SLA_Ref!$A$1:$B$8,2,FALSE),"") -> 5 | J19: =IF(A19="","",IF(B19="",IF(TODAY()-A19>I19,"ATRASADA","EM ANDAMENTO"),IF(B19-A19>I19,"ATRASADA","NO PRAZO"))) -> NO PRAZO | K19: =Tabela2[[#This Row],[SLA Padrão]]-Tabela2[[#This Row],[SLA Atendimento]] -> 11 | M19: 1534.96 | N19: 1534.96 | O19: BRL | P19: =Tabela2[[#This Row],[Proposta Inicial]]-Tabela2[[#This Row],[Proposta Negociada]] -> 0 | Q19: =Tabela2[[#This Row],[Proposta Negociada]]/Tabela2[[#This Row],[Proposta Inicial]]-1 -> 0 | S19: RC 10001664 - REGULARIZAÇÃO - Envio de amostra de MREC para Solvay - CPTR | T19: 450000239 | W19: 02449-0726 | X19: Sim | Y19: Não
A20: 46206 | B20: 46209 | C20: =IF(OR(A20="",B20=""),"",B20-A20) -> 3 | D20: Michel Bernardes | E20: ENVIRONMENT | F20: EHS Treinamentos | G20: Spot | H20: Serviço Normal | I20: =IFERROR(VLOOKUP(H20,SLA_Ref!$A$1:$B$8,2,FALSE),"") -> 15 | J20: =IF(A20="","",IF(B20="",IF(TODAY()-A20>I20,"ATRASADA","EM ANDAMENTO"),IF(B20-A20>I20,"ATRASADA","NO PRAZO"))) -> NO PRAZO | K20: =Tabela2[[#This Row],[SLA Padrão]]-Tabela2[[#This Row],[SLA Atendimento]] -> 12 | M20: 3000 | N20: 2500 | O20: BRL | P20: =Tabela2[[#This Row],[Proposta Inicial]]-Tabela2[[#This Row],[Proposta Negociada]] -> 500 | Q20: =Tabela2[[#This Row],[Proposta Negociada]]/Tabela2[[#This Row],[Proposta Inicial]]-1 -> -0.16666667 | R20: Cost Avoidance | S20: RC 10001699 - Monitoramento de Ruído - CPTR | T20: 450000240 | X20: Não | Y20: Sim
A21: 46206 | B21: 46209 | C21: =IF(OR(A21="",B21=""),"",B21-A21) -> 3 | D21: Amanda Salvi | E21: GEOLOGICAL EXPLORATION | F21: Casa Sao Juliao Comercio de Tintas Ltda | G21: Spot | H21: Material Urgente | I21: =IFERROR(VLOOKUP(H21,SLA_Ref!$A$1:$B$8,2,FALSE),"") -> 3 | J21: =IF(A21="","",IF(B21="",IF(TODAY()-A21>I21,"ATRASADA","EM ANDAMENTO"),IF(B21-A21>I21,"ATRASADA","NO PRAZO"))) -> NO PRAZO | K21: =Tabela2[[#This Row],[SLA Padrão]]-Tabela2[[#This Row],[SLA Atendimento]] -> 0 | M21: 145 | N21: 130 | O21: BRL | P21: =Tabela2[[#This Row],[Proposta Inicial]]-Tabela2[[#This Row],[Proposta Negociada]] -> 15 | Q21: =Tabela2[[#This Row],[Proposta Negociada]]/Tabela2[[#This Row],[Proposta Inicial]]-1 -> -0.10344828 | R21: Cost Avoidance | S21: RC 10001704 | T21: 450000241 | X21: Sim | Y21: Sim
A22: 46213 | B22: 46210 | C22: =IF(OR(A22="",B22=""),"",B22-A22) -> -3 | D22: Amanda Salvi | E22: CPTR | F22: Eletrochoque Comercial Eletrica LTda | G22: Spot | H22: Regularização | I22: =IFERROR(VLOOKUP(H22,SLA_Ref!$A$1:$B$8,2,FALSE),"") -> 30 | J22: =IF(A22="","",IF(B22="",IF(TODAY()-A22>I22,"ATRASADA","EM ANDAMENTO"),IF(B22-A22>I22,"ATRASADA","NO PRAZO"))) -> NO PRAZO | K22: =Tabela2[[#This Row],[SLA Padrão]]-Tabela2[[#This Row],[SLA Atendimento]] -> 33 | M22: 197.9 | N22: 197.9 | O22: BRL | P22: =Tabela2[[#This Row],[Proposta Inicial]]-Tabela2[[#This Row],[Proposta Negociada]] -> 0 | Q22: =Tabela2[[#This Row],[Proposta Negociada]]/Tabela2[[#This Row],[Proposta Inicial]]-1 -> 0 | S22: Regularização - Instalação do Tanque e Agitador 3110TH001 | T22: 450000243 | X22: Sim | Y22: Sim
A23: 46209 | B23: 46206 | C23: =IF(OR(A23="",B23=""),"",B23-A23) -> -3 | D23: Amanda Salvi | E23: ADMINISTRATIVE | F23: Disk Limpeza Total Ltda | G23: Spot | H23: Regularização | I23: =IFERROR(VLOOKUP(H23,SLA_Ref!$A$1:$B$8,2,FALSE),"") -> 30 | J23: =IF(A23="","",IF(B23="",IF(TODAY()-A23>I23,"ATRASADA","EM ANDAMENTO"),IF(B23-A23>I23,"ATRASADA","NO PRAZO"))) -> NO PRAZO | K23: =Tabela2[[#This Row],[SLA Padrão]]-Tabela2[[#This Row],[SLA Atendimento]] -> 33 | M23: 448.01 | N23: 448.01 | O23: BRL | P23: =Tabela2[[#This Row],[Proposta Inicial]]-Tabela2[[#This Row],[Proposta Negociada]] -> 0 | Q23: =Tabela2[[#This Row],[Proposta Negociada]]/Tabela2[[#This Row],[Proposta Inicial]]-1 -> 0 | S23: RC 10001693 - Itens de Limpeza Argentina Mall | T23: 450000244 | X23: Sim | Y23: Sim
A24: 46209 | B24: 46210 | C24: =IF(OR(A24="",B24=""),"",B24-A24) -> 1 | D24: Michel Bernardes | E24: HSE | F24: 1000 Marcas | G24: Spot | H24: Material Normal | I24: =IFERROR(VLOOKUP(H24,SLA_Ref!$A$1:$B$8,2,FALSE),"") -> 8 | J24: =IF(A24="","",IF(B24="",IF(TODAY()-A24>I24,"ATRASADA","EM ANDAMENTO"),IF(B24-A24>I24,"ATRASADA","NO PRAZO"))) -> NO PRAZO | K24: =Tabela2[[#This Row],[SLA Padrão]]-Tabela2[[#This Row],[SLA Atendimento]] -> 7 | M24: 3202.8 | N24: 3042.72 | O24: BRL | P24: =Tabela2[[#This Row],[Proposta Inicial]]-Tabela2[[#This Row],[Proposta Negociada]] -> 160.08 | Q24: =Tabela2[[#This Row],[Proposta Negociada]]/Tabela2[[#This Row],[Proposta Inicial]]-1 -> -0.049981266 | R24: Cost Avoidance | S24: RC 10001703 - Botinas de segurança com sistema anti-torção - Marluvas (CA nº 34550) | T24: 450000245 | W24: 735221 | X24: Sim | Y24: Não
A25: 46210 | B25: 46210 | C25: =IF(OR(A25="",B25=""),"",B25-A25) -> 0 | D25: Michel Bernardes | E25: PURCHASING | F25: Poços Print | G25: Spot | H25: Material Normal | I25: =IFERROR(VLOOKUP(H25,SLA_Ref!$A$1:$B$8,2,FALSE),"") -> 8 | J25: =IF(A25="","",IF(B25="",IF(TODAY()-A25>I25,"ATRASADA","EM ANDAMENTO"),IF(B25-A25>I25,"ATRASADA","NO PRAZO"))) -> NO PRAZO | K25: =Tabela2[[#This Row],[SLA Padrão]]-Tabela2[[#This Row],[SLA Atendimento]] -> 8 | M25: 400 | N25: 400 | O25: BRL | P25: =Tabela2[[#This Row],[Proposta Inicial]]-Tabela2[[#This Row],[Proposta Negociada]] -> 0 | Q25: =Tabela2[[#This Row],[Proposta Negociada]]/Tabela2[[#This Row],[Proposta Inicial]]-1 -> 0 | S25: RC 10001698 - Tintas Epson 544 para Impressora EcoTank | T25: 450000246 | W25: 1178 | X25: Sim | Y25: Sim
A26: 46205 | B26: 46211 | C26: =IF(OR(A26="",B26=""),"",B26-A26) -> 6 | D26: Michel Bernardes | E26: CPTR | F26: alpha Abras | G26: Spot | H26: Material Normal | I26: =IFERROR(VLOOKUP(H26,SLA_Ref!$A$1:$B$8,2,FALSE),"") -> 8 | J26: =IF(A26="","",IF(B26="",IF(TODAY()-A26>I26,"ATRASADA","EM ANDAMENTO"),IF(B26-A26>I26,"ATRASADA","NO PRAZO"))) -> NO PRAZO | K26: =Tabela2[[#This Row],[SLA Padrão]]-Tabela2[[#This Row],[SLA Atendimento]] -> 2 | M26: 494.1 | N26: 494.1 | O26: BRL | P26: =Tabela2[[#This Row],[Proposta Inicial]]-Tabela2[[#This Row],[Proposta Negociada]] -> 0 | Q26: =Tabela2[[#This Row],[Proposta Negociada]]/Tabela2[[#This Row],[Proposta Inicial]]-1 -> 0 | S26: RC 10001692 - Abraçadeiras de nylon – CPTR | T26: 450000248 | W26: 214453 | X26: Sim | Y26: Sim
A27: 46188 | B27: 46206 | C27: =IF(OR(A27="",B27=""),"",B27-A27) -> 18 | D27: Amanda Salvi | E27: ADMINISTRATIVE | F27: Deiseane Alves | G27: Spot | H27: Material Normal | I27: =IFERROR(VLOOKUP(H27,SLA_Ref!$A$1:$B$8,2,FALSE),"") -> 8 | J27: =IF(A27="","",IF(B27="",IF(TODAY()-A27>I27,"ATRASADA","EM ANDAMENTO"),IF(B27-A27>I27,"ATRASADA","NO PRAZO"))) -> ATRASADA | K27: =Tabela2[[#This Row],[SLA Padrão]]-Tabela2[[#This Row],[SLA Atendimento]] -> -10 | M27: 1450 | N27: 1000 | O27: BRL | P27: =Tabela2[[#This Row],[Proposta Inicial]]-Tabela2[[#This Row],[Proposta Negociada]] -> 450 | Q27: =Tabela2[[#This Row],[Proposta Negociada]]/Tabela2[[#This Row],[Proposta Inicial]]-1 -> -0.31034483 | R27: Cost Avoidance | S27: RC 10001593 - Gaveteiro com Chave para Compras, Facilities e Frota | T27: 450000250 | X27: Não | Y27: Sim
A28: 46204 | B28: 46206 | C28: =IF(OR(A28="",B28=""),"",B28-A28) -> 2 | D28: Michel Bernardes | E28: COMMUNITY RELATIONS | F28: Borges Comecio e Equipamentos | G28: Spot | H28: Material Normal | I28: =IFERROR(VLOOKUP(H28,SLA_Ref!$A$1:$B$8,2,FALSE),"") -> 8 | J28: =IF(A28="","",IF(B28="",IF(TODAY()-A28>I28,"ATRASADA","EM ANDAMENTO"),IF(B28-A28>I28,"ATRASADA","NO PRAZO"))) -> NO PRAZO | K28: =Tabela2[[#This Row],[SLA Padrão]]-Tabela2[[#This Row],[SLA Atendimento]] -> 6 | M28: 692 | N28: 692 | O28: BRL | P28: =Tabela2[[#This Row],[Proposta Inicial]]-Tabela2[[#This Row],[Proposta Negociada]] -> 0 | Q28: =Tabela2[[#This Row],[Proposta Negociada]]/Tabela2[[#This Row],[Proposta Inicial]]-1 -> 0 | S28: RC 10001677 - Tela para projeção CPTR | T28: 450000251 | W28: 1408253 | X28: Sim | Y28: Não
A29: 46202 | B29: 46205 | C29: =IF(OR(A29="",B29=""),"",B29-A29) -> 3 | D29: Michel Bernardes | E29: GEOLOGICAL EXPLORATION | F29: Alpha Brasil Goiania | G29: Spot | H29: Material Normal | I29: =IFERROR(VLOOKUP(H29,SLA_Ref!$A$1:$B$8,2,FALSE),"") -> 8 | J29: =IF(A29="","",IF(B29="",IF(TODAY()-A29>I29,"ATRASADA","EM ANDAMENTO"),IF(B29-A29>I29,"ATRASADA","NO PRAZO"))) -> NO PRAZO | K29: =Tabela2[[#This Row],[SLA Padrão]]-Tabela2[[#This Row],[SLA Atendimento]] -> 5 | M29: 170.3 | N29: 170.3 | O29: BRL | P29: =Tabela2[[#This Row],[Proposta Inicial]]-Tabela2[[#This Row],[Proposta Negociada]] -> 0 | Q29: =Tabela2[[#This Row],[Proposta Negociada]]/Tabela2[[#This Row],[Proposta Inicial]]-1 -> 0 | S29: RC 10001656 - Pisante traseiro direito (TXP8I65) | T29: 450000252 | W29: 3487 | X29: Sim | Y29: Não
A30: 46202 | B30: 46205 | C30: =IF(OR(A30="",B30=""),"",B30-A30) -> 3 | D30: Michel Bernardes | E30: GEOLOGICAL EXPLORATION | F30: truck Shop Comercio LTDA | G30: Spot | H30: Material Normal | I30: =IFERROR(VLOOKUP(H30,SLA_Ref!$A$1:$B$8,2,FALSE),"") -> 8 | J30: =IF(A30="","",IF(B30="",IF(TODAY()-A30>I30,"ATRASADA","EM ANDAMENTO"),IF(B30-A30>I30,"ATRASADA","NO PRAZO"))) -> NO PRAZO | K30: =Tabela2[[#This Row],[SLA Padrão]]-Tabela2[[#This Row],[SLA Atendimento]] -> 5 | M30: 58.38 | N30: 58.38 | O30: BRL | P30: =Tabela2[[#This Row],[Proposta Inicial]]-Tabela2[[#This Row],[Proposta Negociada]] -> 0 | Q30: =Tabela2[[#This Row],[Proposta Negociada]]/Tabela2[[#This Row],[Proposta Inicial]]-1 -> 0 | S30: RC 10001647 - Calços para caminhonete | T30: 450000253 | W30: 18005 | X30: Sim | Y30: Não
A31: 46205 | B31: 46211 | C31: =IF(OR(A31="",B31=""),"",B31-A31) -> 6 | D31: Michel Bernardes | E31: CPTR | F31: A.M Marques Produtos para Laboratórios | G31: Spot | H31: Material Normal | I31: =IFERROR(VLOOKUP(H31,SLA_Ref!$A$1:$B$8,2,FALSE),"") -> 8 | J31: =IF(A31="","",IF(B31="",IF(TODAY()-A31>I31,"ATRASADA","EM ANDAMENTO"),IF(B31-A31>I31,"ATRASADA","NO PRAZO"))) -> NO PRAZO | K31: =Tabela2[[#This Row],[SLA Padrão]]-Tabela2[[#This Row],[SLA Atendimento]] -> 2 | M31: 30 | N31: 30 | O31: BRL | P31: =Tabela2[[#This Row],[Proposta Inicial]]-Tabela2[[#This Row],[Proposta Negociada]] -> 0 | Q31: =Tabela2[[#This Row],[Proposta Negociada]]/Tabela2[[#This Row],[Proposta Inicial]]-1 -> 0 | S31: RC 10001649 - Papel filtro para kitassato | T31: 450000254 | W31: 323297 | X31: Sim | Y31: Não
A32: 46206 | B32: 46216 | C32: =IF(OR(A32="",B32=""),"",B32-A32) -> 10 | D32: Michel Bernardes | E32: CPTR | F32: Watson-Marlow | G32: Spot | H32: Material Normal | I32: =IFERROR(VLOOKUP(H32,SLA_Ref!$A$1:$B$8,2,FALSE),"") -> 8 | J32: =IF(A32="","",IF(B32="",IF(TODAY()-A32>I32,"ATRASADA","EM ANDAMENTO"),IF(B32-A32>I32,"ATRASADA","NO PRAZO"))) -> ATRASADA | K32: =Tabela2[[#This Row],[SLA Padrão]]-Tabela2[[#This Row],[SLA Atendimento]] -> -2 | M32: =31541.559+2000 -> 33541.559 | N32: 30039.58 | O32: BRL | P32: =Tabela2[[#This Row],[Proposta Inicial]]-Tabela2[[#This Row],[Proposta Negociada]] -> 3501.979 | Q32: =Tabela2[[#This Row],[Proposta Negociada]]/Tabela2[[#This Row],[Proposta Inicial]]-1 -> -0.10440716 | R32: Cost Avoidance | S32: Melhoria Processo: Bomba recirculação espessadores | T32: 450000255 | X32: Não | Y32: Não
A33: 46211 | B33: 46212 | C33: =IF(OR(A33="",B33=""),"",B33-A33) -> 1 | D33: Michel Bernardes | E33: HUMAN RESOURCES | F33: A.S.D Atividades Fisicas e Fitnes | G33: Spot | H33: Material Normal | I33: =IFERROR(VLOOKUP(H33,SLA_Ref!$A$1:$B$8,2,FALSE),"") -> 8 | J33: =IF(A33="","",IF(B33="",IF(TODAY()-A33>I33,"ATRASADA","EM ANDAMENTO"),IF(B33-A33>I33,"ATRASADA","NO PRAZO"))) -> NO PRAZO | K33: =Tabela2[[#This Row],[SLA Padrão]]-Tabela2[[#This Row],[SLA Atendimento]] -> 7 | M33: 499 | N33: 499 | O33: BRL | P33: =Tabela2[[#This Row],[Proposta Inicial]]-Tabela2[[#This Row],[Proposta Negociada]] -> 0 | Q33: =Tabela2[[#This Row],[Proposta Negociada]]/Tabela2[[#This Row],[Proposta Inicial]]-1 -> 0 | S33: RC 10001652 - Podium de Premiação (para uso no Viridis Fitness Day) | T33: 450000256 | W33: 66922 | X33: Sim | Y33: Não
A34: 46210 | B34: 46211 | C34: =IF(OR(A34="",B34=""),"",B34-A34) -> 1 | D34: Michel Bernardes | E34: HUMAN RESOURCES | F34: 67.607.454 FELIPE DETOFOLI VIEIRA | G34: Spot | H34: Material Urgente | I34: =IFERROR(VLOOKUP(H34,SLA_Ref!$A$1:$B$8,2,FALSE),"") -> 3 | J34: =IF(A34="","",IF(B34="",IF(TODAY()-A34>I34,"ATRASADA","EM ANDAMENTO"),IF(B34-A34>I34,"ATRASADA","NO PRAZO"))) -> NO PRAZO | K34: =Tabela2[[#This Row],[SLA Padrão]]-Tabela2[[#This Row],[SLA Atendimento]] -> 2 | M34: =100*49 -> 4900 | N34: 4000 | O34: BRL | P34: =Tabela2[[#This Row],[Proposta Inicial]]-Tabela2[[#This Row],[Proposta Negociada]] -> 900 | Q34: =Tabela2[[#This Row],[Proposta Negociada]]/Tabela2[[#This Row],[Proposta Inicial]]-1 -> -0.18367347 | R34: Cost Avoidance | S34: RC 10001665 - Porta-retrato personalizado inauguração Programa RARO | T34: 450000257 | W34: 32 | X34: Sim | Y34: Não
A35: 46210 | B35: 46213 | C35: =IF(OR(A35="",B35=""),"",B35-A35) -> 3 | D35: Michel Bernardes | E35: IT | F35: BluePex | G35: Contrato | H35: Serviço Normal | I35: =IFERROR(VLOOKUP(H35,SLA_Ref!$A$1:$B$8,2,FALSE),"") -> 15 | J35: =IF(A35="","",IF(B35="",IF(TODAY()-A35>I35,"ATRASADA","EM ANDAMENTO"),IF(B35-A35>I35,"ATRASADA","NO PRAZO"))) -> NO PRAZO | K35: =Tabela2[[#This Row],[SLA Padrão]]-Tabela2[[#This Row],[SLA Atendimento]] -> 12 | M35: 16020 | N35: 9924.96 | O35: BRL | P35: =Tabela2[[#This Row],[Proposta Inicial]]-Tabela2[[#This Row],[Proposta Negociada]] -> 6095.04 | Q35: =Tabela2[[#This Row],[Proposta Negociada]]/Tabela2[[#This Row],[Proposta Inicial]]-1 -> -0.38046442 | R35: Cost Avoidance | S35: RC 10001669 - Firewall | T35: 450000258 | X35: Não | Y35: Não
A36: 46199 | B36: 46209 | C36: =IF(OR(A36="",B36=""),"",B36-A36) -> 10 | D36: Amanda Salvi | E36: CAPEX | F36: Sherwin Williams do Brasil Industrial e Comercio Ltda | G36: Spot | H36: Material Normal | I36: =IFERROR(VLOOKUP(H36,SLA_Ref!$A$1:$B$8,2,FALSE),"") -> 8 | J36: =IF(A36="","",IF(B36="",IF(TODAY()-A36>I36,"ATRASADA","EM ANDAMENTO"),IF(B36-A36>I36,"ATRASADA","NO PRAZO"))) -> ATRASADA | K36: =Tabela2[[#This Row],[SLA Padrão]]-Tabela2[[#This Row],[SLA Atendimento]] -> -2 | M36: 2397.46 | N36: 2397.46 | O36: BRL | P36: =Tabela2[[#This Row],[Proposta Inicial]]-Tabela2[[#This Row],[Proposta Negociada]] -> 0 | Q36: =Tabela2[[#This Row],[Proposta Negociada]]/Tabela2[[#This Row],[Proposta Inicial]]-1 -> 0 | S36: Tintas para pintura do caminho seguro do CPTR | T36: 450000259 | X36: Não | Y36: Sim
A37: 46212 | B37: 46212 | C37: =IF(OR(A37="",B37=""),"",B37-A37) -> 0 | D37: Amanda Salvi | E37: ADMINISTRATIVE | F37: Esvatech e Cia Comercio e Representacoes | G37: Spot | H37: Material Normal | I37: =IFERROR(VLOOKUP(H37,SLA_Ref!$A$1:$B$8,2,FALSE),"") -> 8 | J37: =IF(A37="","",IF(B37="",IF(TODAY()-A37>I37,"ATRASADA","EM ANDAMENTO"),IF(B37-A37>I37,"ATRASADA","NO PRAZO"))) -> NO PRAZO | K37: =Tabela2[[#This Row],[SLA Padrão]]-Tabela2[[#This Row],[SLA Atendimento]] -> 8 | M37: 127 | N37: 127 | O37: BRL | P37: =Tabela2[[#This Row],[Proposta Inicial]]-Tabela2[[#This Row],[Proposta Negociada]] -> 0 | Q37: =Tabela2[[#This Row],[Proposta Negociada]]/Tabela2[[#This Row],[Proposta Inicial]]-1 -> 0 | S37: RC 10001722 - Fruteira Refeitório Argentina Mall | T37: 450000260 | X37: Sim | Y37: Não
A38: 46212 | B38: 46213 | C38: =IF(OR(A38="",B38=""),"",B38-A38) -> 1 | D38: Michel Bernardes | E38: CPTR | F38: Máximo Laboratório | G38: Spot | H38: Material Normal | I38: =IFERROR(VLOOKUP(H38,SLA_Ref!$A$1:$B$8,2,FALSE),"") -> 8 | J38: =IF(A38="","",IF(B38="",IF(TODAY()-A38>I38,"ATRASADA","EM ANDAMENTO"),IF(B38-A38>I38,"ATRASADA","NO PRAZO"))) -> NO PRAZO | K38: =Tabela2[[#This Row],[SLA Padrão]]-Tabela2[[#This Row],[SLA Atendimento]] -> 7 | M38: 899 | N38: 399 | O38: BRL | P38: =Tabela2[[#This Row],[Proposta Inicial]]-Tabela2[[#This Row],[Proposta Negociada]] -> 500 | Q38: =Tabela2[[#This Row],[Proposta Negociada]]/Tabela2[[#This Row],[Proposta Inicial]]-1 -> -0.55617353 | R38: Cost Avoidance | S38: RC 10001723 - Tubos Falcon 15 mL para Laboratório – CPTR | T38: 450000261 | W38: 76868 | X38: sim | Y38: Não
A39: 46212 | B39: 46214 | C39: =IF(OR(A39="",B39=""),"",B39-A39) -> 2 | D39: Michel Bernardes | E39: COMMUNITY RELATIONS | F39: Fabiana Brinquedos | G39: Spot | H39: Serviço Urgente | I39: =IFERROR(VLOOKUP(H39,SLA_Ref!$A$1:$B$8,2,FALSE),"") -> 5 | J39: =IF(A39="","",IF(B39="",IF(TODAY()-A39>I39,"ATRASADA","EM ANDAMENTO"),IF(B39-A39>I39,"ATRASADA","NO PRAZO"))) -> NO PRAZO | K39: =Tabela2[[#This Row],[SLA Padrão]]-Tabela2[[#This Row],[SLA Atendimento]] -> 3 | M39: 13000 | N39: 12000 | O39: BRL | P39: =Tabela2[[#This Row],[Proposta Inicial]]-Tabela2[[#This Row],[Proposta Negociada]] -> 1000 | Q39: =Tabela2[[#This Row],[Proposta Negociada]]/Tabela2[[#This Row],[Proposta Inicial]]-1 -> -0.076923077 | R39: Cost Avoidance | S39: RC 10001720 - Aluguel de Brinquedos Infláveis, pipoca e algodão doce para o Festival de Inverno | T39: 450000262 | W39: 236 | X39: Sim | Y39: Sim
A40: 46213 | B40: 46216 | C40: =IF(OR(A40="",B40=""),"",B40-A40) -> 3 | D40: Michel Bernardes | E40: HSE | F40: Alpha Abras | G40: Spot | H40: Material Normal | I40: =IFERROR(VLOOKUP(H40,SLA_Ref!$A$1:$B$8,2,FALSE),"") -> 8 | J40: =IF(A40="","",IF(B40="",IF(TODAY()-A40>I40,"ATRASADA","EM ANDAMENTO"),IF(B40-A40>I40,"ATRASADA","NO PRAZO"))) -> NO PRAZO | K40: =Tabela2[[#This Row],[SLA Padrão]]-Tabela2[[#This Row],[SLA Atendimento]] -> 5 | M40: 179 | N40: 161 | O40: BRL | P40: =Tabela2[[#This Row],[Proposta Inicial]]-Tabela2[[#This Row],[Proposta Negociada]] -> 18 | Q40: =Tabela2[[#This Row],[Proposta Negociada]]/Tabela2[[#This Row],[Proposta Inicial]]-1 -> -0.10055866 | R40: Cost Avoidance | S40: RC 10001729 - EPI - Kit Eco Florestal Genesis Capacete L340c Malha Plástica Adaptador Libus | T40: 450000265 | W40: 214583 | X40: Sim | Y40: Sim
...

Sheet Controle RCs
A1: RC's recebidas 2026 | B1: Janeiro | C1: Fevereiro | D1: Março | E1: Abril | F1: Maio | G1: Junho | H1: Julho | I1: Agosto | J1: Setembro | K1: Outubro | L1: Novembro | M1: Dezembro | N1: TOTAL
A2: OPEX | B2: 79 | C2: 70 | D2: 109 | E2: 115 | F2: 147 | N2: 520
A3: CAPEX | B3: 56 | C3: 48 | D3: 76 | E3: 75 | F3: 37 | N3: 292
M4: TOTAL | N4: 812
A5: RC's recebidas 2026 - URGENTES | B5: Janeiro | C5: Fevereiro | D5: Março | E5: Abril | F5: Maio | G5: Junho | H5: Julho | I5: Agosto | J5: Setembro | K5: Outubro | L5: Novembro | M5: Dezembro | N5: TOTAL
A6: OPEX | B6: 33 | C6: 30 | D6: 57 | E6: 56 | F6: 83 | N6: 259
A7: CAPEX | B7: 45 | C7: 36 | D7: 59 | E7: 53 | F7: 19 | N7: 212
M8: TOTAL | N8: 471
N9: 0.58004926
N10: ~59,1%
A11: RC's Status | B11: Janeiro | C11: Fevereiro | D11: Março | E11: Abril | F11: Maio | G11: Junho | H11: Julho | I11: Agosto | J11: Setembro | K11: Outubro | L11: Novembro | M11: Dezembro | N11: TOTAL
A12: OPEX - Abertas
A13: OPEX - Concluídas
A14: CAPEX - Abertas
A15: CAPEX - Concluídas
A17: RC's recebidas 2026 REGULARIZAÇÃO | B17: Janeiro | C17: Fevereiro | D17: Março | E17: Abril | F17: Maio | G17: Junho | H17: Julho | I17: Agosto | J17: Setembro | K17: Outubro | L17: Novembro | M17: Dezembro | N17: TOTAL
A18: TOTAL | B18: - | C18: - | D18: - | E18: - | F18: 18 | N18: 18
A21: Ano | B21: RC's recebidas OPEX | C21: RC's recebidas CAPEX | D21: TOTAL RC's recebidas
A22: 2024 | B22: 464 | C22: 0 | D22: 464
A23: 2025 | B23: 598 | C23: 94 | D23: 692
A24: 2026 | B24: 251 | C24: 170 | D24: =SUM(B24:C24) -> 421

Sheet Gestão de Contratos

Sheet Cadastro Fornecedores
A1: CÓD. VIRIDIS FORNECEDOR | B1: CATEGORIA ATUALIZADA | C1: RAZÃO SOCIAL | D1: NOME FANTASIA | E1: CNPJ | F1: ENDEREÇO | G1: CIDADE | H1: UF | I1: CEP | J1: PAIS | K1: CONTATO PRINCIPAL | L1: TELEFONE | M1: E-MAIL | N1: COMPRA INTERNET | O1: FORNECEDOR LOCAL
A2: 300001 | B2: Materiais e Suprimentos Industriais | C2: GOTAGUA FILTROS LTDA | D2: GOTAGUA | E2: 06.298.134/0001--17 | F2: Alameda Dona Tereza Cristina, 46 lloja | G2: SÃO BERNARDO DO CAMPO | H2: SP | I2: 9770330 | J2: BRASIL | K2: Luiz Carlos Blasques Junior | L2: (11) 4123-6109 | M2: atendimento@gotagua.com.br | N2: SIM | O2: NÃO
A3: 300002 | B3: Equipamentos de Proteção Individual | C3: ALPHA ABRAS COMERCIO DE ABRASIVOS LTDA | D3: ALPHABRAS | E3: 05.159.343/0001-56 | F3: TRAVESSA CORONEL VIRGILIO SILVA, 102 BE, BASTOS | G3: POÇOS DE CALDAS | H3: MG | I3: 37701489 | J3: BRASIL | K3: Adriano | L3: (35) 99829-7179 | M3: adriano.alphabras@gmail.com | N3: NÃO | O3: SIM
A4: 300003 | B4: Softwares e Licenças | C4: D-SAAS TECNOLOGIA EM DESENVOLVIMENTO DE SOFTWARE LTDA | D4: DIMEP | E4: 46.220.369/0001-00 | F4: Avenida Mofarrej, n.º 840, 2º andar, Vila Leopoldina | G4: SÃO PAULO | H4: SP | I4: 5311000 | J4: BRASIL | K4: Marcelo Mariano | L4: (35) 98861-0140 | M4: prontec.marcelo@uol.com.br | N4: NÃO | O4: NÃO
A5: 300004 | B5: Fornecimento de Produtos de Limpeza | C5: DISK LIMPEZA TOTAL LTDA | D5: DISK LIMPEZA | E5: 10.757.521/0001-41 | F5: R São Paulo, 276 Centro | G5: POÇOS DE CALDAS | H5: MG | I5: 3701001 | J5: BRASIL | K5: Luciano Dias | L5: (35) 3721-2647 | M5: limpezatotal09@hotmail.com | N5: NÃO | O5: SIM
A6: 300005 | B6: Fornecedores de Alimentação | C6: PAO DE MEL E BOMBOCADO LTDA EPP | D6: BOMBOCADO | E6: 66.444.787/0003-50 | F6: R Paraiba, 182 Centro | G6: POÇOS DE CALDAS | H6: MG | I6: 37701022 | J6: BRASIL | K6: Adriana | L6: (35) 9802-1949 | N6: NÃO | O6: SIM
A7: 300006 | B7: Fornecedores de Alimentação | C7: PADARIA KI SABOR LTDA | D7: KI SABOR | E7: 05.439.722/0001-60 | F7: Avenida Espanha, 165 Parque das Naçoes | G7: POÇOS DE CALDAS | H7: MG | I7: 37706181 | J7: BRASIL | K7: Ana Cristina Pacheco | L7: (35) 3715-7404 | M7: padaria_padariakisabor@hotmail.com | N7: NÃO | O7: SIM
A8: 300007 | B8: Corretora de Imóveis | C8: AINER GESTÃO DE NEGÓCIOS E AVALIAÇÕES LTDA | D8: CENER | E8: 56.746.425/0001-07 | F8: Rua Benedito Lobato, nº 634, apto 502, bairro São João, | G8: CONSELHEIRO LAFAIETE | H8: MG | I8: 36404154 | J8: BRASIL | K8: Kathrein Maia | L8: (31) 99797-0502 | M8: KATHREINRM@HOTMAIL.COM | N8: NÃO | O8: NÃO
A9: 300008 | B9: Consultoria Técnica e Ambiental | C9: 3EM-MINERACAO E GEOLOGIA LTDA-ME | D9: 3EM | E9: 27.584.269/0001-19 | F9: Avenida Portugal, n.º 3250, loja 09 e 10, Pavimento 1, Bairro Jardim Atlântico | G9: BELO HORIZONTE | H9: MG | I9: 31560000 | J9: BRASIL | K9: Lúcio Miranda Camêlo | L9: (31) 99777-2049 | M9: lucio@3emmg.com.br | N9: NÃO | O9: NÃO
A10: 300009 | B10: Telefonia e Planos Corporativos | C10: ALGAR TELECOM S/A | D10: ALGAR | E10: 71.208.516/0001-74 | F10: Rua José Alves Garcia, n.º 415, bairro Brasil | G10: UBERLÂNDIA | H10: MG | I10: 38400668 | J10: BRASIL | K10: Vagner Manoel | L10: (43) 98801-1100 | M10: vagner.manoel@algarempresarial.com | N10: NÃO | O10: NÃO
A11: 300010 | B11: Softwares e Licenças | C11: ALGER CONSULTORIA SOCIOAMBIENTAL LTDA | D11: ALGER | E11: 40.586.743/0001-00 | F11: Rua Sebastião Fabiano Dias, 210, Salas 701 a 708, Bairro Belvedere | G11: BELO HORIZONTE | H11: MG | I11: 30320690 | J11: BRASIL | K11: Regina Cruz | L11: (31) 99812-5747 | M11: regina@algerconsultoria.com.br | N11: NÃO | O11: NÃO
A12: 300011 | B12: Marketing, Comunicação e Gráfica | C12: AMANDA CORRÊA DE MORAIS COSTA | D12: IDEOLOGICO | E12: 34.686.648/0001-85 | F12: Rua Papula Vermelha, 245, bairro Havaí | G12: BELO HORIZONTE | H12: MG | I12: 30555190 | J12: BRASIL | K12: Amanda Correa | L12: (31) 99107-4175 | M12: contato@igeologico.com.br | N12: NÃO | O12: NÃO
A13: 300012 | B13: Coleta de Resíduos Comuns e Recicláveis | C13: ANTONIO APARECIDO ALMEIDA ME (CONEXÃO SA) | D13: CONEXAO AS | E13: 30.386.654/0001-66 | F13: Rua Pedro Marcante, n.º 10, apartamento 2, bairro Boa Esperança II, | G13: POÇOS DE CALDAS | H13: MG | I13: 37704524 | J13: BRASIL | K13: Antonio Aparecido Almeida | L13: (35) 99239-8501 | M13: toninho@conexaosa.com | N13: NÃO | O13: SIM
A14: 300013 | B14: Locação de Espaços e Equipamentos | C14: ARGENTINA MALL LTDA | D14: ARGENTINA MALL | E14: 21.746.130/0001-48 | F14: Rua Barros Cobra, nº 305, Conjunto 52, Sala 02 – Centro | G14: POÇOS DE CALDAS | H14: MG | I14: 37701822 | J14: BRASIL | K14: Fernanda Pereira | L14: (35) 99984-1552 | M14: fernanda@evoluaimoveis.com.br | N14: NÃO | O14: SIM
A15: 300014 | B15: Seguros | C15: AVLA SEGUROS BRASIL S.A. (GIFT SEGUROS) | D15: AVLA | E15: 41.182.665/0001-40 | F15: Rua Olimpíadas, nº 205, cj. nº. 32, Vila Olímpia | G15: SÃO PAULO | H15: SP | I15: 4551000 | J15: BRASIL | K15: Jhonattan de Oliveira | L15: (19) 99847-3338 | M15: jhonattan@giftseguros.com | N15: NÃO | O15: NÃO
A16: 300015 | B16: Softwares e Licenças | C16: BNA EQUIPAMENTOS E SISTEMAS DO BRASIL, COMÉRCIO, IMPORTACAO E EXPORTACAO LTDA | D16: BNA | E16: 05.569.016/0001-33 | F16: Rua Desembargador Leao Starling, n.º 200, bairro Ouro Preto | G16: BELO HORIZONTE | H16: MG | I16: 31310370 | J16: BRASIL | K16: Beck Nader | L16: (31) 98438-3411 | M16: beckn@bnaconsultoria.com | N16: NÃO | O16: NÃO
A17: 300016 | B17: Escritório de Contabilidade | C17: CGC CONTABILIDADE GERAL E CONSULTORIA | D17: CGC | E17: 65.165.649/0001-08 | F17: Rua Professor Moraes, 476 - loja 04 - Bairro Savassi | G17: BELO HORIZONTE | H17: MG | I17: 30150370 | J17: BRASIL | K17: Ricardo Santos | L17: (31) 99192-5133 | M17: ricardo@cgccontabilidade.com.br | N17: NÃO | O17: NÃO
A18: 300017 | B18: Consultoria Técnica e Ambiental | C18: CLAM MEIO AMBIENTE LTDA | D18: CLAM | E18: 08.803.534/0001-68 | F18: Rua Sergipe, 1333, Sala 901, bairro Savassi | G18: BELO HORIZONTE | H18: MG | I18: 30130134 | J18: BRASIL | K18: Patricia Medeiros | L18: (31) 98379-2040 | M18: patricia.medeiros@clam.com.br | N18: NÃO | O18: NÃO
... A30: 300029 | B30: Clínicas de Medicina do Trabalho | C30: L.C.B - ATIVIDADES MEDICAS EIRELI | D30: MEDNET | E30: 36.608.298/0001-64 | F30: Rua Pernambuco, 444, Centro - Sala 4 | G30: POÇOS DE CALDAS | H30: MG | I30: 37701021 | J30: BRASIL | K30: Aline Dias | L30: (35) 99670-1143 | M30: com01@mednet-pocoscaldas.com.br | N30: NÃO | O30: SIM
A31: 300030 | B31: Monitoramento Eletrônico (Câmeras e Alarmes) | C31: LARISSA S. RODRIGUES - ME (LOTUS) | D31: LOTUS | E31: 14.022.179/0001-92 | F31: Av. Juscelino Kubitscheck de Oliveira, 46 - Parque Vivaldi Leite Ribeiro | G31: POÇOS DE CALDAS | H31: MG | I31: 37701-186 | J31: BRASIL | K31: Amanda Del Sarto | L31: (35) 99829-0087 | M31: administrativo@centraldemonitoramento24hs.com.br | N31: NÃO | O31: SIM
A32: 300031 | B32: Seguros | C32: MAPFRE SEGUROS GERAIS S.A (AJG) | D32: MAPFRE | E32: 61.074.175/0001-38 | F32: Av. das Naçoes Unidas, 14.261 - ALA A, Vila Gertrudes | G32: SÃO PAULO | H32: SP | I32: 4794000 | J32: BRASIL | K32: Eduarda Guido | L32: (11) 96596-7644 | M32: Eduarda_Guido@ajg.com> | N32: NÃO | O32: NÃO
A33: 300032 | B33: Consultoria Técnica e Ambiental | C33: MDGEO SERVIÇOS DE HIDREOLOGIA LTDA | D33: MDGEO | E33: 38.625.927/0001-90 | F33: Rua Santa Bárbara, nº 162, Sagrada Família | G33: BELO HORIZONTE | H33: MG | I33: 31030150 | J33: BRASIL | K33: Daniel Coelho | L33: (31) 3482-9959 | M33: Daniel.Coelho@mdgeo.com.br | N33: NÃO | O33: NÃO
A34: 300033 | B34: Serviços Jurídicos e de Compliance | C34: MENDES E BARSI SOCIEDADE DE ADVOGADOS | D34: MENDES E BARSI | E34: 35.377.825/0001-04 | F34: Rua Prefeito Chagas, n.º 489, sala 01, centro, | G34: POÇOS DE CALDAS | H34: MG | I34: 37701734 | J34: BRASIL | K34: Marcinha / Pri | L34: (35) 99129-7700 / (35) 99779-9000 | M34: juridico@viridismining.com.au | N34: NÃO | O34: SIM
A35: 300034 | B35: Consultoria Técnica e Ambiental | C35: PROMINAS PROJETOS E SERVIÇOS DE MINERAÇÃO LTDA | D35: PROMINAS | E35: 01.955.849/0001-81 | F35: Rua Paraíba, n.º 1465, sala 1101, 11º andar, bairro Savassi | G35: BELO HORIZONTE | H35: MG | I35: 30130148 | J35: BRASIL | K35: Marlos Roges | L35: (31) 3497-4274 | M35: marlos.roges@prominasmining.com | N35: NÃO | O35: NÃO
A36: 300035 | B36: Programas de Educação e Impacto Social | C36: RHINO PRODUÇOES LTDA | D36: O MUNDO DE RHINO | E36: 55.962.620/0001-01 | F36: Rua Capitão Afonso Junqueira, nº 240, Complemento 53, Centro | G36: POÇOS DE CALDAS | H36: MG | I36: 37701042 | J36: BRASIL | K36: Marco Noronha | L36: (35) 98821-1661 | M36: omundorhino@gmail.com | N36: NÃO | O36: SIM
A37: 300036 | B37: Tecnologia da Informação (TI) | C37: RONAN LEITE CHIMINAZO | D37: RONAN | E37: 54.737.662/0001-78 | F37: Av. Jaçanã Musa dos Santos, n.º 405, bairro Conjunto Habitacional | G37: POÇOS DE CALDAS | H37: MG | I37: 37706206 | J37: BRASIL | K37: Ronan Chiminazzo | L37: (35) 99199-5615 | M37: ronanlc@4techinformatica.com.br | N37: NÃO | O37: SIM
A38: 300037 | B38: Softwares e Licenças | C38: SEEQUENT - BENTLEY SYSTEMS BRASIL LTDA. | D38: SEEQUENT | E38: 01.712.235/0001-79 | F38: Avenida Paulista, 2537 – Bela Vista - 9 andar, sala 09-114 | G38: SÃO PAULO | H38: SP | I38: 1310100 | J38: BRASIL | K38: Ana Pinheiro | L38: (31) 99089-3270 | M38: Ana.Pinheiro@seequent.com | N38: NÃO | O38: NÃO
A39: 300038 | B39: Programas de Educação e Impacto Social | C39: SENAI - SERVIÇO NACIONAL DE APRENDIZAGEM INDUSTRIAL | D39: SENAI | E39: 03.773.700/0026-65 | F39: Rua Pedro Barbosa, n.º 600, bairro Monte Verde | G39: POÇOS DE CALDAS | H39: MG | I39: 37705309 | J39: BRASIL | K39: Gustavo Costa Mendes | L39: (35) 3729-2613 | M39: gc.mendes@fiemg.com.br | N39: NÃO | O39: SIM
A40: 300039 | B40: Química e Análises Laboratoriais | C40: SIEVERT LABORATÓRIO E SERVIÇOS AMBIENTAIS LTDA, | D40: SIEVERT | E40: 06.960.855/0001-40 | F40: Rua Olavio Virgílio dos Santos, n.º 31, bairro Vila Califórnia | G40: SÃO PAULO | H40: SP | I40: 4775220 | J40: BRASIL | K40: Priscila Nogueira | L40: (19) 98455-9001 | M40: vendas@glplab.com.br | N40: NÃO | O40: NÃO
A41: 300040 | B41: Locação de Veículos | C41: TERRAPLENAGEM PAULA E COSTA LTDA ME | D41: PAULA E COSTA | E41: 11.009.825/0001-93 | F41: Avenida Doutor Ubirajara Machado de Moraes, n.º 636, bairro Jd. Nova Aparecida | G41: POÇOS DE CALDAS | H41: MG | I41: 37704016 | J41: BRASIL | K41: Wilson Reis | L41: (35) 99191-0061 | M41: pcterraplanagem@hotmail.com | N41: NÃO | O41: SIM
A42: 300041 | B42: Locação de Espaços e Equipamentos | C42: VSTAY GESTAO IMOBILIARIA LTDA | D42: VSTAY | E42: 53.709.633/0001-30 | F42: Rua Capitão Afonso Junqueira, 290, Sala 05, Centro | G42: POÇOS DE CALDAS | H42: MG | I42: 37701042 | J42: BRASIL | K42: Thiago Muniz | L42: (35) 98401-9369 | M42: thiago@construtoravital.com | N42: NÃO | O42: SIM
A43: 300042 | B43: Marketing, Comunicação e Gráfica | C43: SEMPRE EDITORA LTDA | D43: JORNAL O TEMPO | E43: 26.198.515/0004-84 | F43: Avenida Babita Camargos, 1645 Cidade Industrial | G43: CONTAGEM | H43: MG | I43: 32210180 | J43: BRASIL | K43: Mirian Andrade | L43: (31) 8347-8576 | M43: mirian.santo@otempo.com.br | N43: NÃO | O43: NÃO
A44: 300043 | B44: Locação de Firewall | C44: BLUEPEX TECNOLOGIA S.A. | D44: BLUEPEX | E44: 02.227.843/0001-50 | F44: Rua Wilson Vitório Coletta, 157 | G44: LIMEIRA | H44: SP | I44: 13482225 | J44: BRASIL | L44: (35) 98818-2228 | M44: larissa.venancio@bluepex.com | N44: NÃO | O44: NÃO
A45: 300044 | B45: Fornecedores de Alimentação | C45: SODRE MIGUEL LTDA | D45: SAN MICHEL | E45: 19.709.344/0001-00 | F45: Rua Pernambuco, 1000 Centro | G45: POÇOS DE CALDAS | H45: MG | I45: 37701021 | J45: BRASIL | L45: (35) 3729-1515 | N45: NÃO | O45: SIM
A46: 300045 | B46: Materiais e Suprimentos Industriais | C46: SOUZA & MONTEIRO LTDA | D46: LOJA DO VARAL | E46: 03.208.846/0001-00 | F46: Rua Correa Neto, 256 Centro | G46: POÇOS DE CALDAS | H46: MG | I46: 37701016 | J46: BRASIL | L46: (35) 3714-1777 | N46: NÃO | O46: SIM
A47: 300046 | B47: Materiais e Suprimentos Industriais | C47: SUPRITEC TECNOLOGIA EM SEGURANÇA LTDA | D47: SUPRITEC | E47: 08.268.970/0004-27 | F47: Rua Vereador Joao Siqueira Loyola, Jd Campos Eliseos | G47: POÇOS DE CALDAS | H47: MG | I47: 37706029 | J47: BRASIL | K47: Guilherme | L47: (35) 9811-2215 | M47: guilherme.faria@gruposupritec.com.br | N47: NÃO | O47: SIM
A48: 300047 | B48: Fornecimento de Combustíveis e Lubrificantes | C48: MAXIMA SHOP | D48: MAXIMASHOP. COM COMERCIAL EIRELI | E48: 15.392.064/0001-52 | F48: Rua Antonio Coelho dos Santos, 37 Boqueirao | G48: CURITIBA | H48: PR | I48: 81750140 | J48: BRASIL | L48: (41) 8807-7755 | N48: SIM | O48: NÃO
A49: 300048 | B49: Fornecedores de Alimentação | C49: CENTERNARIO EXPRESS | D49: CENTENARIO EXPRESS LTDA | E49: 56.908.192/0001-93 | F49: Rua Argentina, 455 Jd Quisisana | G49: POÇOS DE CALDAS | H49: MG | I49: 37701248 | J49: BRASIL | N49: NÃO | O49: SIM
A50: 300049 | B50: Materiais e Suprimentos Industriais | C50: LOGMAIS ETIQUETAS ADESIVAS LTDA | D50: LOGGMAIS | E50: 42.287.977/0001-81 | F50: Rua Vicente de Carvalho, 134 Sala 1 | G50: CAMBUCI | H50: SP | I50: 1521020 | J50: BRASIL | N50: SIM | O50: NÃO
A51: 300050 | B51: Tecnologia da Informação (TI) | C51: TUDO SOBRE ELETRONICOS LTDA | D51: TUDO SOBRE ELETRONICOS LTDA | E51: 55.602.536/0001-79 | F51: Rua Manuel Gaya, 620 CP 13014, Vila Nova Mazzei | G51: SÃO PAULO | H51: SP | I51: 2313970 | J51: BRASIL | N51: SIM | O51: NÃO
...

Sheet RCs
A1: Ano | B1: Mês | C1: Nº Mês | D1: Indicador | E1: Categoria | F1: Quantidade
A2: 2026 | B2: Janeiro | C2: 1 | D2: RC Recebidas | E2: OPEX | F2: 79
A3: 2026 | B3: Janeiro | C3: 1 | D3: RC Recebidas | E3: CAPEX | F3: 56
A4: 2026 | B4: Janeiro | C4: 1 | D4: RC Urgentes | E4: OPEX | F4: 33
A5: 2026 | B5: Janeiro | C5: 1 | D5: RC Urgentes | E5: CAPEX | F5: 45
A6: 2026 | B6: Fevereiro | C6: 2 | D6: RC Recebidas | E6: OPEX | F6: 70
A7: 2026 | B7: Fevereiro | C7: 2 | D7: RC Recebidas | E7: CAPEX | F7: 48
A8: 2026 | B8: Fevereiro | C8: 2 | D8: RC Urgentes | E8: OPEX | F8: 30
A9: 2026 | B9: Fevereiro | C9: 2 | D9: RC Urgentes | E9: CAPEX | F9: 36
A10: 2026 | B10: Março | C10: 3 | D10: RC Recebidas | E10: OPEX | F10: 109
A11: 2026 | B11: Março | C11: 3 | D11: RC Recebidas | E11: CAPEX | F11: 76
A12: 2026 | B12: Março | C12: 3 | D12: RC Urgentes | E12: OPEX | F12: 57
A13: 2026 | B13: Março | C13: 3 | D13: RC Urgentes | E13: CAPEX | F13: 59
... A21: 2026 | B21: Maio | C21: 5 | D21: RC Urgentes | E21: CAPEX | F21: 19

Sheet Evolução RCs
A1: Ano | B1: RC's Recebidas OPEX | C1: RC's Recebidas CAPEX
A2: 2024 | B2: 464 | C2: 0 | D2: =SUM(B2:C2) -> 464
A3: 2025 | B3: 598 | C3: 94 | D3: =SUM(B3:C3) -> 692
A4: 2026 | B4: 251 | C4: 170 | D4: =SUM(B4:C4) -> 421

Sheet Planilha1
A1: Spot | B1: Material Urgente | C1: 3 | D1: Amanda Salvi | F1: ADMINISTRATIVE
A2: Contrato | B2: Material Normal | C2: 8 | D2: Michel Bernardes | F2: CAPEX
B3: Serviço Urgente | C3: 5 | D3: Leandro Abreu | F3: COMMUNICATION
B4: Serviço Normal | C4: 15 | D4: Júlia Guidorizzi | F4: COMMUNITY RELATIONS
B5: Regularização | C5: 30 | F5: CPTR
B6: Contrato Contínuo Simples | C6: 30 | F6: EXECUTIVE MANAGEMENT
B7: Contrato Contínuo Complexo | C7: 60 | F7: FINANCE
B8: Importação | C8: 20 | F8: GEOLOGICAL EXPLORATION
F9: HSE
F10: HUMAN RESOURCES
F11: LEGAL
F12: MINE PLANNING
F13: PROJECTS
F14: PURCHASING
F15: REGULATORY
F16: SUSTAINABILITY
F17: IT
F18: ENVIRONMENT
F19: MKT

Sheet SLA_Ref
A1: Material Urgente | B1: 3
A2: Material Normal | B2: 8
A3: Serviço Normal | B3: 15
A4: Serviço Urgente | B4: 5
A5: Regularização | B5: 30
A6: Contrato Contínuo Simples | B6: 30
A7: Contrato Contínuo Complexo | B7: 60
A8: Importação | B8: 20
